import userModel from "../../models/users.model.js";

class UserManagerDB {
    getUsers = async () => {
        try {
            const users = await userModel.find();
            return users;
        } catch (error) {
            console.log("Error fetching carts:", error)
        }
    }

    getIdUser = async (idUser) => {
        try {
            const user = await userModel.findOne({ _id: idUser});
            if (!user) {
                // throw new Error(`No se encontró ningún usuario con el ID: ${idUser}`);  //se lanza una excepcion, para capturarla desde el Route
                //throw new Error(`No se encontró ningún usuario con el ID: `);
                //console.log("En userMnager.js, No se hallo un usuario")

            }
            return user;
        } catch (error) {
            throw error; // Vuelve a lanzar la excepción para que la ruta la maneje el Router
        }
    }

    getEmailUser = async (email) => {
        try {
            const user = await userModel.findOne({ email: email });
            //Se valida en los llamantes
            // if (!user) {
            //     throw new Error(`No se encontró ningún usuario con el correo electrónico: ${email}`);
            // }
            return user;
        } catch (error) {
            // Aquí podrías realizar un registro del error antes de volver a lanzarlo
            console.error("Error en getEmailUser:", error);
            throw error; // Vuelve a lanzar la excepción para que la ruta la maneje el Router
        }
    }
    
    // getEmailUser = async (email) => {
    //     try {
    //         const user = await userModel.findOne({email:email})
    //         if (!user) {
    //              throw new Error(`No se encontró ningún usuario con el ID: ${email}`);  //se lanza una excepcion, para capturarla desde el Route
    //             //throw new Error(`No se encontró ningún usuario con el ID: `);
    //             //console.log("En userMnager.js, No se hallo un usuario")

    //         }
    //         return user
    //     } catch (error) {
    //         throw error; // Vuelve a lanzar la excepción para que la ruta la maneje el Router
    //     }
    // }

    updateUser = async (uid, user) => {
        try {
            const result = await userModel.updateOne({ _id: uid }, { $set: user });
            return user
        } catch (error) {
            throw error; // Vuelve a lanzar la excepción para que la ruta la maneje el Router
        }
    }

    createUser = async (user) => {
        try {
            const result = userModel.create(user);
            return result
        } catch (error) {
            console.log("Error en lectura de archivos!!");
            throw error;
        }
    }

    deleteUser = async (uid) => {
        try {
             const result = await userModel.deleteOne({ _id: uid });
            return result;
        } catch (error) {
            throw error; // Vuelve a lanzar la excepción para que la ruta la maneje el Router
        }
    }
}

export {UserManagerDB};